#VRML_SIM R2023a utf8

EXTERNPROTO "https://raw.githubusercontent.com/cyberbotics/webots/R2023a/projects/objects/backgrounds/protos/TexturedBackground.proto"
EXTERNPROTO "https://raw.githubusercontent.com/cyberbotics/webots/R2023a/projects/objects/backgrounds/protos/TexturedBackgroundLight.proto"
EXTERNPROTO "https://raw.githubusercontent.com/cyberbotics/webots/R2023a/projects/objects/floors/protos/Floor.proto"

WorldInfo {
}
Viewpoint {
  orientation -0.08845636306573693 0.16273583790067955 0.9826965548407841 1.0105166694671532
  position -0.515868066361625 -0.7847131049604936 0.3581201128596221
}
TexturedBackground {
}
TexturedBackgroundLight {
}
Floor {
}
Robot {
  translation 0 0 0.1
  children [
    DEF WheelL HingeJoint {
      jointParameters HingeJointParameters {
      }
      device [
        DEF WheelL RotationalMotor {
          name "WheelL"
        }
      ]
      endPoint Solid {
        translation -0.175 0 0
        rotation 0 -1 0 1.5708
        children [
          DEF Wheel Shape {
            appearance PBRAppearance {
              baseColor 0 1 0.498039
            }
            geometry Cylinder {
              height 0.05
              radius 0.1
            }
          }
        ]
        boundingObject USE Wheel
        physics Physics {
        }
      }
    }
    DEF WheelR HingeJoint {
      jointParameters HingeJointParameters {
      }
      device [
        DEF WheelR RotationalMotor {
          name "WheelR"
        }
      ]
      endPoint Solid {
        translation 0.175 0 0
        rotation 0 -1 0 1.5708
        children [
          DEF Wheel Shape {
            appearance PBRAppearance {
              baseColor 0 1 0.498039
            }
            geometry Cylinder {
              height 0.05
              radius 0.1
            }
          }
        ]
        name "solid(1)"
        boundingObject USE Wheel
        physics Physics {
        }
      }
    }
    DEF Body Shape {
      appearance PBRAppearance {
      }
      geometry Box {
        size 0.3 0.15 0.05
      }
    }
  ]
  boundingObject USE Body
  physics Physics {
  }
}
Solid {
  translation 0 0 0.18
  children [
    Shape {
      appearance PBRAppearance {
        baseColor 0.333333 0 1
      }
      geometry DEF weight Box {
        size 0.1 0.1 0.1
      }
    }
  ]
  boundingObject USE weight
  physics Physics {
  }
}
